Workbook

Sheet Budget
A1: year | B1: month | C1: business_unit | D1: budgeted_revenue | E1: budgeted_expense | F1: Actual _expense _helper col | G1: BUDGETED EXPENSE_helper col | H1: BUDGET VARIANCE | I1: Budget_Variance_Outlier_Flag
A2: 2022 | B2: 1 | C2: Retail | D2: 1530660 | E2: 1259760 | F2: =ABS(SUMIFS(Financial_Transactions!C:C,Financial_Transactions!F:F,Budget!C2,Financial_Transactions!L:L,Budget!B2,Financial_Transactions!M:M,Budget!A2)) -> 5412829.7 | G2: =SUMIFS(E:E,C:C,Budget!C2,B:B,Budget!B2,A:A,Budget!A2) -> 1259760 | H2: =F2-G2 -> 4153069.7 | I2: =IF(H2="","", IF(OR(H2 < EDA_Outlier_Analysis!$M$10, H2 > EDA_Outlier_Analysis!$M$11), "Outlier", "Normal")) -> Normal
A3: 2022 | B3: 1 | C3: Enterprise | D3: 1689240 | E3: 1152615 | F3: =ABS(SUMIFS(Financial_Transactions!C:C,Financial_Transactions!F:F,Budget!C3,Financial_Transactions!L:L,Budget!B3,Financial_Transactions!M:M,Budget!A3)) -> 6939353.9 | G3: =SUMIFS(E:E,C:C,Budget!C3,B:B,Budget!B3,A:A,Budget!A3) -> 1152615 | H3: =F3-G3 -> 5786738.9 | I3: =IF(H3="","", IF(OR(H3 < EDA_Outlier_Analysis!$M$10, H3 > EDA_Outlier_Analysis!$M$11), "Outlier", "Normal")) -> Normal
A4: 2022 | B4: 1 | C4: Online | D4: 2069088 | E4: 1776169 | F4: =ABS(SUMIFS(Financial_Transactions!C:C,Financial_Transactions!F:F,Budget!C4,Financial_Transactions!L:L,Budget!B4,Financial_Transactions!M:M,Budget!A4)) -> 6584819.9 | G4: =SUMIFS(E:E,C:C,Budget!C4,B:B,Budget!B4,A:A,Budget!A4) -> 1776169 | H4: =F4-G4 -> 4808650.9 | I4: =IF(H4="","", IF(OR(H4 < EDA_Outlier_Analysis!$M$10, H4 > EDA_Outlier_Analysis!$M$11), "Outlier", "Normal")) -> Normal
A5: 2022 | B5: 2 | C5: Retail | D5: 1836984 | E5: 1201730 | F5: =ABS(SUMIFS(Financial_Transactions!C:C,Financial_Transactions!F:F,Budget!C5,Financial_Transactions!L:L,Budget!B5,Financial_Transactions!M:M,Budget!A5)) -> 7080862.7 | G5: =SUMIFS(E:E,C:C,Budget!C5,B:B,Budget!B5,A:A,Budget!A5) -> 1201730 | H5: =F5-G5 -> 5879132.7 | I5: =IF(H5="","", IF(OR(H5 < EDA_Outlier_Analysis!$M$10, H5 > EDA_Outlier_Analysis!$M$11), "Outlier", "Normal")) -> Normal
A6: 2022 | B6: 2 | C6: Enterprise | D6: 1923012 | E6: 1454263 | F6: =ABS(SUMIFS(Financial_Transactions!C:C,Financial_Transactions!F:F,Budget!C6,Financial_Transactions!L:L,Budget!B6,Financial_Transactions!M:M,Budget!A6)) -> 5236074.5 | G6: =SUMIFS(E:E,C:C,Budget!C6,B:B,Budget!B6,A:A,Budget!A6) -> 1454263 | H6: =F6-G6 -> 3781811.5 | I6: =IF(H6="","", IF(OR(H6 < EDA_Outlier_Analysis!$M$10, H6 > EDA_Outlier_Analysis!$M$11), "Outlier", "Normal")) -> Normal
A7: 2022 | B7: 2 | C7: Online | D7: 1516272 | E7: 1117069 | F7: =ABS(SUMIFS(Financial_Transactions!C:C,Financial_Transactions!F:F,Budget!C7,Financial_Transactions!L:L,Budget!B7,Financial_Transactions!M:M,Budget!A7)) -> 4984247.5 | G7: =SUMIFS(E:E,C:C,Budget!C7,B:B,Budget!B7,A:A,Budget!A7) -> 1117069 | H7: =F7-G7 -> 3867178.5 | I7: =IF(H7="","", IF(OR(H7 < EDA_Outlier_Analysis!$M$10, H7 > EDA_Outlier_Analysis!$M$11), "Outlier", "Normal")) -> Normal
A8: 2022 | B8: 3 | C8: Retail | D8: 1510920 | E8: 1106833 | F8: =ABS(SUMIFS(Financial_Transactions!C:C,Financial_Transactions!F:F,Budget!C8,Financial_Transactions!L:L,Budget!B8,Financial_Transactions!M:M,Budget!A8)) -> 4751090.3 | G8: =SUMIFS(E:E,C:C,Budget!C8,B:B,Budget!B8,A:A,Budget!A8) -> 1106833 | H8: =F8-G8 -> 3644257.3 | I8: =IF(H8="","", IF(OR(H8 < EDA_Outlier_Analysis!$M$10, H8 > EDA_Outlier_Analysis!$M$11), "Outlier", "Normal")) -> Normal
A9: 2022 | B9: 3 | C9: Enterprise | D9: 1576692 | E9: 959653 | F9: =ABS(SUMIFS(Financial_Transactions!C:C,Financial_Transactions!F:F,Budget!C9,Financial_Transactions!L:L,Budget!B9,Financial_Transactions!M:M,Budget!A9)) -> 7072144.3 | G9: =SUMIFS(E:E,C:C,Budget!C9,B:B,Budget!B9,A:A,Budget!A9) -> 959653 | H9: =F9-G9 -> 6112491.3 | I9: =IF(H9="","", IF(OR(H9 < EDA_Outlier_Analysis!$M$10, H9 > EDA_Outlier_Analysis!$M$11), "Outlier", "Normal")) -> Normal
A10: 2022 | B10: 3 | C10: Online | D10: 2119464 | E10: 1677676 | F10: =ABS(SUMIFS(Financial_Transactions!C:C,Financial_Transactions!F:F,Budget!C10,Financial_Transactions!L:L,Budget!B10,Financial_Transactions!M:M,Budget!A10)) -> 7911633 | G10: =SUMIFS(E:E,C:C,Budget!C10,B:B,Budget!B10,A:A,Budget!A10) -> 1677676 | H10: =F10-G10 -> 6233957 | I10: =IF(H10="","", IF(OR(H10 < EDA_Outlier_Analysis!$M$10, H10 > EDA_Outlier_Analysis!$M$11), "Outlier", "Normal")) -> Normal
A11: 2022 | B11: 4 | C11: Retail | D11: 1731204 | E11: 1275919 | F11: =ABS(SUMIFS(Financial_Transactions!C:C,Financial_Transactions!F:F,Budget!C11,Financial_Transactions!L:L,Budget!B11,Financial_Transactions!M:M,Budget!A11)) -> 7684580.3 | G11: =SUMIFS(E:E,C:C,Budget!C11,B:B,Budget!B11,A:A,Budget!A11) -> 1275919 | H11: =F11-G11 -> 6408661.3 | I11: =IF(H11="","", IF(OR(H11 < EDA_Outlier_Analysis!$M$10, H11 > EDA_Outlier_Analysis!$M$11), "Outlier", "Normal")) -> Normal
A12: 2022 | B12: 4 | C12: Enterprise | D12: 2042184 | E12: 1592655 | F12: =ABS(SUMIFS(Financial_Transactions!C:C,Financial_Transactions!F:F,Budget!C12,Financial_Transactions!L:L,Budget!B12,Financial_Transactions!M:M,Budget!A12)) -> 8597751.4 | G12: =SUMIFS(E:E,C:C,Budget!C12,B:B,Budget!B12,A:A,Budget!A12) -> 1592655 | H12: =F12-G12 -> 7005096.4 | I12: =IF(H12="","", IF(OR(H12 < EDA_Outlier_Analysis!$M$10, H12 > EDA_Outlier_Analysis!$M$11), "Outlier", "Normal")) -> Normal
A13: 2022 | B13: 4 | C13: Online | D13: 2132844 | E13: 1388082 | F13: =ABS(SUMIFS(Financial_Transactions!C:C,Financial_Transactions!F:F,Budget!C13,Financial_Transactions!L:L,Budget!B13,Financial_Transactions!M:M,Budget!A13)) -> 9740610.3 | G13: =SUMIFS(E:E,C:C,Budget!C13,B:B,Budget!B13,A:A,Budget!A13) -> 1388082 | H13: =F13-G13 -> 8352528.3 | I13: =IF(H13="","", IF(OR(H13 < EDA_Outlier_Analysis!$M$10, H13 > EDA_Outlier_Analysis!$M$11), "Outlier", "Normal")) -> Normal
... A73: 2023 | B73: 12 | C73: Online | D73: 2263008 | E73: 1662605 | F73: =ABS(SUMIFS(Financial_Transactions!C:C,Financial_Transactions!F:F,Budget!C73,Financial_Transactions!L:L,Budget!B73,Financial_Transactions!M:M,Budget!A73)) -> 15321099 | G73: =SUMIFS(E:E,C:C,Budget!C73,B:B,Budget!B73,A:A,Budget!A73) -> 1662605 | H73: =F73-G73 -> 13658494 | I73: =IF(H73="","", IF(OR(H73 < EDA_Outlier_Analysis!$M$10, H73 > EDA_Outlier_Analysis!$M$11), "Outlier", "Normal")) -> Normal

Sheet Customers
A1: customer_id | B1: customer_name | C1: segment | D1: join_date | E1: region | F1: status
A2: CUST10000 | B2: Johnson, Olson and Smith | C2: Online | D2: 43918 | E2: North | F2: Active
A3: CUST10001 | B3: Colon-Valdez | C3: Enterprise | D3: 43146 | E3: West | F3: Active
A4: CUST10002 | B4: Henry, Jones and Farley | C4: Online | D4: 44641 | E4: North | F4: Active
A5: CUST10003 | B5: Williams-Dalton | C5: Retail | D5: 44277 | E5: West | F5: Active
A6: CUST10004 | B6: Fisher-Serrano | C6: Enterprise | D6: 43406 | E6: East | F6: Active
A7: CUST10005 | B7: Jennings Ltd | C7: Online | D7: 43663 | E7: South | F7: Active
A8: CUST10006 | B8: Tate-Haas | C8: Retail | D8: 45212 | E8: West | F8: Active
A9: CUST10007 | B9: Brooks, Aguilar and Young | C9: Enterprise | D9: 43234 | E9: North | F9: Active
A10: CUST10008 | B10: Herrera-Ingram | C10: Retail | D10: 43350 | E10: East | F10: Active
A11: CUST10009 | B11: Dunn, Graham and Brown | C11: Retail | D11: 44229 | E11: West | F11: Active
A12: CUST10010 | B12: Moore, Walker and Gutierrez | C12: Retail | D12: 42831 | E12: East | F12: Active
A13: CUST10011 | B13: Turner-Lawson | C13: Enterprise | D13: 42920 | E13: West | F13: Active
... A401: CUST10399 | B401: Marshall-Horne | C401: Enterprise | D401: 43563 | E401: East | F401: Inactive

Sheet Financial_Transactions
A1: transaction_id | B1: transaction_date | C1: amount | D1: account_type | E1: category | F1: business_unit | G1: region | H1: customer_id | I1: vendor_id | J1: description | K1: customer_fk_status | L1: Month | M1: year | N1: Profit _Value | O1: Revenue_Value | P1: Expense_Value | Q1: Revenue_Outlier_Flag | R1: Expense_Outlier_Flag | S1: Profit_Outlier_Flag
A2: TRX100000 | B2: 45172 | C2: -66631.73 | D2: Expense | E2: Supplies | F2: Online | G2: West | I2: VEND1053 | J2: Begin catch control dark practice. | K2: =IF(COUNTIF(Customers!A:A, H2)>0, "Valid", "Invalid") -> Invalid | L2: =TEXT(B2,"m") -> 9 | M2: =TEXT(B2,"yyyy") -> 2023 | N2: =IF(D2="Revenue",C2,-ABS(C2)) -> -66631.73 | O2: =IF(D2="Revenue", C2, "") | P2: =IF(D2="Expense", ABS(C2), "") -> 66631.73 | Q2: =IF(O2="","", IF(OR(O2<EDA_Outlier_Analysis!$C$10, O2>EDA_Outlier_Analysis!$C$11), "Outlier", "Normal")) | R2: =IF(P2="","", IF(OR(P2 < EDA_Outlier_Analysis!$F$7, P2 > EDA_Outlier_Analysis!$F$8), "Outlier", "Normal")) -> Outlier | S2: =IF(N2="","", IF(OR(N2 <EDA_Outlier_Analysis!$I$10, N2 > EDA_Outlier_Analysis!$I$11), "Outlier", "Normal")) -> Normal
A3: TRX100001 | B3: 45182 | C3: -54305.58 | D3: Expense | E3: Utilities | F3: Enterprise | G3: East | I3: VEND1059 | J3: Style guy soldier boy energy above. | K3: =IF(COUNTIF(Customers!A:A, H3)>0, "Valid", "Invalid") -> Invalid | L3: =TEXT(B3,"m") -> 9 | M3: =TEXT(B3,"yyyy") -> 2023 | N3: =IF(D3="Revenue",C3,-ABS(C3)) -> -54305.58 | O3: =IF(D3="Revenue", C3, "") | P3: =IF(D3="Expense", ABS(C3), "") -> 54305.58 | Q3: =IF(O3="","", IF(OR(O3<EDA_Outlier_Analysis!$C$10, O3>EDA_Outlier_Analysis!$C$11), "Outlier", "Normal")) | R3: =IF(P3="","", IF(OR(P3 < EDA_Outlier_Analysis!$F$7, P3 > EDA_Outlier_Analysis!$F$8), "Outlier", "Normal")) -> Outlier | S3: =IF(N3="","", IF(OR(N3 <EDA_Outlier_Analysis!$I$10, N3 > EDA_Outlier_Analysis!$I$11), "Outlier", "Normal")) -> Normal
A4: TRX100002 | B4: 45104 | C4: 146074.92 | D4: Revenue | E4: Subscription | F4: Online | G4: East | H4: CUST10122 | J4: Skill surface drug personal western. | K4: =IF(COUNTIF(Customers!A:A, H4)>0, "Valid", "Invalid") -> Valid | L4: =TEXT(B4,"m") -> 6 | M4: =TEXT(B4,"yyyy") -> 2023 | N4: =IF(D4="Revenue",C4,-ABS(C4)) -> 146074.92 | O4: =IF(D4="Revenue", C4, "") -> 146074.92 | P4: =IF(D4="Expense", ABS(C4), "") | Q4: =IF(O4="","", IF(OR(O4<EDA_Outlier_Analysis!$C$10, O4>EDA_Outlier_Analysis!$C$11), "Outlier", "Normal")) -> Normal | R4: =IF(P4="","", IF(OR(P4 < EDA_Outlier_Analysis!$F$7, P4 > EDA_Outlier_Analysis!$F$8), "Outlier", "Normal")) | S4: =IF(N4="","", IF(OR(N4 <EDA_Outlier_Analysis!$I$10, N4 > EDA_Outlier_Analysis!$I$11), "Outlier", "Normal")) -> Normal
A5: TRX100003 | B5: 45102 | C5: 212157.95 | D5: Revenue | E5: Service | F5: Enterprise | G5: West | H5: CUST10027 | J5: Develop many it I rich floor decide. | K5: =IF(COUNTIF(Customers!A:A, H5)>0, "Valid", "Invalid") -> Valid | L5: =TEXT(B5,"m") -> 6 | M5: =TEXT(B5,"yyyy") -> 2023 | N5: =IF(D5="Revenue",C5,-ABS(C5)) -> 212157.95 | O5: =IF(D5="Revenue", C5, "") -> 212157.95 | P5: =IF(D5="Expense", ABS(C5), "") | Q5: =IF(O5="","", IF(OR(O5<EDA_Outlier_Analysis!$C$10, O5>EDA_Outlier_Analysis!$C$11), "Outlier", "Normal")) -> Normal | R5: =IF(P5="","", IF(OR(P5 < EDA_Outlier_Analysis!$F$7, P5 > EDA_Outlier_Analysis!$F$8), "Outlier", "Normal")) | S5: =IF(N5="","", IF(OR(N5 <EDA_Outlier_Analysis!$I$10, N5 > EDA_Outlier_Analysis!$I$11), "Outlier", "Normal")) -> Normal
A6: TRX100004 | B6: 45245 | C6: -35944.73 | D6: Expense | E6: Rent | F6: Enterprise | G6: North | I6: VEND1046 | J6: Choose thought teach never. | K6: =IF(COUNTIF(Customers!A:A, H6)>0, "Valid", "Invalid") -> Invalid | L6: =TEXT(B6,"m") -> 11 | M6: =TEXT(B6,"yyyy") -> 2023 | N6: =IF(D6="Revenue",C6,-ABS(C6)) -> -35944.73 | O6: =IF(D6="Revenue", C6, "") | P6: =IF(D6="Expense", ABS(C6), "") -> 35944.73 | Q6: =IF(O6="","", IF(OR(O6<EDA_Outlier_Analysis!$C$10, O6>EDA_Outlier_Analysis!$C$11), "Outlier", "Normal")) | R6: =IF(P6="","", IF(OR(P6 < EDA_Outlier_Analysis!$F$7, P6 > EDA_Outlier_Analysis!$F$8), "Outlier", "Normal")) -> Normal | S6: =IF(N6="","", IF(OR(N6 <EDA_Outlier_Analysis!$I$10, N6 > EDA_Outlier_Analysis!$I$11), "Outlier", "Normal")) -> Normal
A7: TRX100005 | B7: 44989 | C7: 90953.83 | D7: Revenue | E7: Service | F7: Retail | G7: South | H7: CUST10332 | J7: Dinner present unit lay course. | K7: =IF(COUNTIF(Customers!A:A, H7)>0, "Valid", "Invalid") -> Valid | L7: =TEXT(B7,"m") -> 3 | M7: =TEXT(B7,"yyyy") -> 2023 | N7: =IF(D7="Revenue",C7,-ABS(C7)) -> 90953.83 | O7: =IF(D7="Revenue", C7, "") -> 90953.83 | P7: =IF(D7="Expense", ABS(C7), "") | Q7: =IF(O7="","", IF(OR(O7<EDA_Outlier_Analysis!$C$10, O7>EDA_Outlier_Analysis!$C$11), "Outlier", "Normal")) -> Normal | R7: =IF(P7="","", IF(OR(P7 < EDA_Outlier_Analysis!$F$7, P7 > EDA_Outlier_Analysis!$F$8), "Outlier", "Normal")) | S7: =IF(N7="","", IF(OR(N7 <EDA_Outlier_Analysis!$I$10, N7 > EDA_Outlier_Analysis!$I$11), "Outlier", "Normal")) -> Normal
A8: TRX100006 | B8: 45115 | C8: 73251.21 | D8: Revenue | E8: Service | F8: Online | G8: West | H8: CUST10270 | J8: Data ago arm care hundred represent wonder. | K8: =IF(COUNTIF(Customers!A:A, H8)>0, "Valid", "Invalid") -> Valid | L8: =TEXT(B8,"m") -> 7 | M8: =TEXT(B8,"yyyy") -> 2023 | N8: =IF(D8="Revenue",C8,-ABS(C8)) -> 73251.21 | O8: =IF(D8="Revenue", C8, "") -> 73251.21 | P8: =IF(D8="Expense", ABS(C8), "") | Q8: =IF(O8="","", IF(OR(O8<EDA_Outlier_Analysis!$C$10, O8>EDA_Outlier_Analysis!$C$11), "Outlier", "Normal")) -> Normal | R8: =IF(P8="","", IF(OR(P8 < EDA_Outlier_Analysis!$F$7, P8 > EDA_Outlier_Analysis!$F$8), "Outlier", "Normal")) | S8: =IF(N8="","", IF(OR(N8 <EDA_Outlier_Analysis!$I$10, N8 > EDA_Outlier_Analysis!$I$11), "Outlier", "Normal")) -> Normal
A9: TRX100007 | B9: 44644 | C9: -21064.02 | D9: Expense | E9: Marketing | F9: Online | G9: East | I9: VEND1115 | J9: Sign such remember range ability. | K9: =IF(COUNTIF(Customers!A:A, H9)>0, "Valid", "Invalid") -> Invalid | L9: =TEXT(B9,"m") -> 3 | M9: =TEXT(B9,"yyyy") -> 2022 | N9: =IF(D9="Revenue",C9,-ABS(C9)) -> -21064.02 | O9: =IF(D9="Revenue", C9, "") | P9: =IF(D9="Expense", ABS(C9), "") -> 21064.02 | Q9: =IF(O9="","", IF(OR(O9<EDA_Outlier_Analysis!$C$10, O9>EDA_Outlier_Analysis!$C$11), "Outlier", "Normal")) | R9: =IF(P9="","", IF(OR(P9 < EDA_Outlier_Analysis!$F$7, P9 > EDA_Outlier_Analysis!$F$8), "Outlier", "Normal")) -> Outlier | S9: =IF(N9="","", IF(OR(N9 <EDA_Outlier_Analysis!$I$10, N9 > EDA_Outlier_Analysis!$I$11), "Outlier", "Normal")) -> Normal
A10: TRX100008 | B10: 44775 | C10: 136347.73 | D10: Revenue | E10: Product | F10: Retail | G10: West | H10: CUST10168 | J10: Poor similar feeling close require probably rather thought. | K10: =IF(COUNTIF(Customers!A:A, H10)>0, "Valid", "Invalid") -> Valid | L10: =TEXT(B10,"m") -> 8 | M10: =TEXT(B10,"yyyy") -> 2022 | N10: =IF(D10="Revenue",C10,-ABS(C10)) -> 136347.73 | O10: =IF(D10="Revenue", C10, "") -> 136347.73 | P10: =IF(D10="Expense", ABS(C10), "") | Q10: =IF(O10="","", IF(OR(O10<EDA_Outlier_Analysis!$C$10, O10>EDA_Outlier_Analysis!$C$11), "Outlier", "Normal")) -> Normal | R10: =IF(P10="","", IF(OR(P10 < EDA_Outlier_Analysis!$F$7, P10 > EDA_Outlier_Analysis!$F$8), "Outlier", "Normal")) | S10: =IF(N10="","", IF(OR(N10 <EDA_Outlier_Analysis!$I$10, N10 > EDA_Outlier_Analysis!$I$11), "Outlier", "Normal")) -> Normal
A11: TRX100009 | B11: 45094 | C11: 159482 | D11: Revenue | E11: Product | F11: Retail | G11: West | H11: CUST10151 | J11: Cause worker statement office able foot. | K11: =IF(COUNTIF(Customers!A:A, H11)>0, "Valid", "Invalid") -> Valid | L11: =TEXT(B11,"m") -> 6 | M11: =TEXT(B11,"yyyy") -> 2023 | N11: =IF(D11="Revenue",C11,-ABS(C11)) -> 159482 | O11: =IF(D11="Revenue", C11, "") -> 159482 | P11: =IF(D11="Expense", ABS(C11), "") | Q11: =IF(O11="","", IF(OR(O11<EDA_Outlier_Analysis!$C$10, O11>EDA_Outlier_Analysis!$C$11), "Outlier", "Normal")) -> Normal | R11: =IF(P11="","", IF(OR(P11 < EDA_Outlier_Analysis!$F$7, P11 > EDA_Outlier_Analysis!$F$8), "Outlier", "Normal")) | S11: =IF(N11="","", IF(OR(N11 <EDA_Outlier_Analysis!$I$10, N11 > EDA_Outlier_Analysis!$I$11), "Outlier", "Normal")) -> Normal
A12: TRX100010 | B12: 44749 | C12: 15882.36 | D12: Equity | E12: Equity | F12: Retail | G12: South | J12: Ready enter quite attack resource list commercial. | K12: =IF(COUNTIF(Customers!A:A, H12)>0, "Valid", "Invalid") -> Invalid | L12: =TEXT(B12,"m") -> 7 | M12: =TEXT(B12,"yyyy") -> 2022 | N12: =IF(D12="Revenue",C12,-ABS(C12)) -> -15882.36 | O12: =IF(D12="Revenue", C12, "") | P12: =IF(D12="Expense", ABS(C12), "") | Q12: =IF(O12="","", IF(OR(O12<EDA_Outlier_Analysis!$C$10, O12>EDA_Outlier_Analysis!$C$11), "Outlier", "Normal")) | R12: =IF(P12="","", IF(OR(P12 < EDA_Outlier_Analysis!$F$7, P12 > EDA_Outlier_Analysis!$F$8), "Outlier", "Normal")) | S12: =IF(N12="","", IF(OR(N12 <EDA_Outlier_Analysis!$I$10, N12 > EDA_Outlier_Analysis!$I$11), "Outlier", "Normal")) -> Normal
A13: TRX100011 | B13: 44781 | C13: 217487.82 | D13: Revenue | E13: Product | F13: Online | G13: North | H13: CUST10353 | J13: Before green media feeling Mr half trouble. | K13: =IF(COUNTIF(Customers!A:A, H13)>0, "Valid", "Invalid") -> Valid | L13: =TEXT(B13,"m") -> 8 | M13: =TEXT(B13,"yyyy") -> 2022 | N13: =IF(D13="Revenue",C13,-ABS(C13)) -> 217487.82 | O13: =IF(D13="Revenue", C13, "") -> 217487.82 | P13: =IF(D13="Expense", ABS(C13), "") | Q13: =IF(O13="","", IF(OR(O13<EDA_Outlier_Analysis!$C$10, O13>EDA_Outlier_Analysis!$C$11), "Outlier", "Normal")) -> Normal | R13: =IF(P13="","", IF(OR(P13 < EDA_Outlier_Analysis!$F$7, P13 > EDA_Outlier_Analysis!$F$8), "Outlier", "Normal")) | S13: =IF(N13="","", IF(OR(N13 <EDA_Outlier_Analysis!$I$10, N13 > EDA_Outlier_Analysis!$I$11), "Outlier", "Normal")) -> Normal
A14: TRX100012 | B14: 45001 | C14: -8913.27 | D14: Expense | E14: Other | F14: Enterprise | G14: East | I14: VEND1067 | J14: Rise discover visit security end buy medical think. | K14: =IF(COUNTIF(Customers!A:A, H14)>0, "Valid", "Invalid") -> Invalid | L14: =TEXT(B14,"m") -> 3 | M14: =TEXT(B14,"yyyy") -> 2023 | N14: =IF(D14="Revenue",C14,-ABS(C14)) -> -8913.27 | O14: =IF(D14="Revenue", C14, "") | P14: =IF(D14="Expense", ABS(C14), "") -> 8913.27 | Q14: =IF(O14="","", IF(OR(O14<EDA_Outlier_Analysis!$C$10, O14>EDA_Outlier_Analysis!$C$11), "Outlier", "Normal")) | R14: =IF(P14="","", IF(OR(P14 < EDA_Outlier_Analysis!$F$7, P14 > EDA_Outlier_Analysis!$F$8), "Outlier", "Normal")) -> Outlier | S14: =IF(N14="","", IF(OR(N14 <EDA_Outlier_Analysis!$I$10, N14 > EDA_Outlier_Analysis!$I$11), "Outlier", "Normal")) -> Normal
A15: TRX100013 | B15: 45270 | C15: 139523.96 | D15: Revenue | E15: Service | F15: Retail | G15: North | H15: CUST10243 | J15: Military line exist little education family world. | K15: =IF(COUNTIF(Customers!A:A, H15)>0, "Valid", "Invalid") -> Valid | L15: =TEXT(B15,"m") -> 12 | M15: =TEXT(B15,"yyyy") -> 2023 | N15: =IF(D15="Revenue",C15,-ABS(C15)) -> 139523.96 | O15: =IF(D15="Revenue", C15, "") -> 139523.96 | P15: =IF(D15="Expense", ABS(C15), "") | Q15: =IF(O15="","", IF(OR(O15<EDA_Outlier_Analysis!$C$10, O15>EDA_Outlier_Analysis!$C$11), "Outlier", "Normal")) -> Normal | R15: =IF(P15="","", IF(OR(P15 < EDA_Outlier_Analysis!$F$7, P15 > EDA_Outlier_Analysis!$F$8), "Outlier", "Normal")) | S15: =IF(N15="","", IF(OR(N15 <EDA_Outlier_Analysis!$I$10, N15 > EDA_Outlier_Analysis!$I$11), "Outlier", "Normal")) -> Normal
A16: TRX100014 | B16: 45125 | C16: 165589.04 | D16: Revenue | E16: Service | F16: Online | G16: East | H16: CUST10357 | J16: Artist place loss morning. | K16: =IF(COUNTIF(Customers!A:A, H16)>0, "Valid", "Invalid") -> Valid | L16: =TEXT(B16,"m") -> 7 | M16: =TEXT(B16,"yyyy") -> 2023 | N16: =IF(D16="Revenue",C16,-ABS(C16)) -> 165589.04 | O16: =IF(D16="Revenue", C16, "") -> 165589.04 | P16: =IF(D16="Expense", ABS(C16), "") | Q16: =IF(O16="","", IF(OR(O16<EDA_Outlier_Analysis!$C$10, O16>EDA_Outlier_Analysis!$C$11), "Outlier", "Normal")) -> Normal | R16: =IF(P16="","", IF(OR(P16 < EDA_Outlier_Analysis!$F$7, P16 > EDA_Outlier_Analysis!$F$8), "Outlier", "Normal")) | S16: =IF(N16="","", IF(OR(N16 <EDA_Outlier_Analysis!$I$10, N16 > EDA_Outlier_Analysis!$I$11), "Outlier", "Normal")) -> Normal
A17: TRX100015 | B17: 44952 | C17: 262541.15 | D17: Revenue | E17: Service | F17: Retail | G17: West | H17: CUST10045 | J17: Game evidence support skill pretty. | K17: =IF(COUNTIF(Customers!A:A, H17)>0, "Valid", "Invalid") -> Valid | L17: =TEXT(B17,"m") -> 1 | M17: =TEXT(B17,"yyyy") -> 2023 | N17: =IF(D17="Revenue",C17,-ABS(C17)) -> 262541.15 | O17: =IF(D17="Revenue", C17, "") -> 262541.15 | P17: =IF(D17="Expense", ABS(C17), "") | Q17: =IF(O17="","", IF(OR(O17<EDA_Outlier_Analysis!$C$10, O17>EDA_Outlier_Analysis!$C$11), "Outlier", "Normal")) -> Normal | R17: =IF(P17="","", IF(OR(P17 < EDA_Outlier_Analysis!$F$7, P17 > EDA_Outlier_Analysis!$F$8), "Outlier", "Normal")) | S17: =IF(N17="","", IF(OR(N17 <EDA_Outlier_Analysis!$I$10, N17 > EDA_Outlier_Analysis!$I$11), "Outlier", "Normal")) -> Normal
A18: TRX100016 | B18: 45087 | C18: 152113.39 | D18: Revenue | E18: Service | F18: Online | G18: South | H18: CUST10120 | J18: Bad author generation decade increase. | K18: =IF(COUNTIF(Customers!A:A, H18)>0, "Valid", "Invalid") -> Valid | L18: =TEXT(B18,"m") -> 6 | M18: =TEXT(B18,"yyyy") -> 2023 | N18: =IF(D18="Revenue",C18,-ABS(C18)) -> 152113.39 | O18: =IF(D18="Revenue", C18, "") -> 152113.39 | P18: =IF(D18="Expense", ABS(C18), "") | Q18: =IF(O18="","", IF(OR(O18<EDA_Outlier_Analysis!$C$10, O18>EDA_Outlier_Analysis!$C$11), "Outlier", "Normal")) -> Normal | R18: =IF(P18="","", IF(OR(P18 < EDA_Outlier_Analysis!$F$7, P18 > EDA_Outlier_Analysis!$F$8), "Outlier", "Normal")) | S18: =IF(N18="","", IF(OR(N18 <EDA_Outlier_Analysis!$I$10, N18 > EDA_Outlier_Analysis!$I$11), "Outlier", "Normal")) -> Normal
A19: TRX100017 | B19: 44726 | C19: 107495.7 | D19: Revenue | E19: Service | F19: Online | G19: North | H19: CUST10228 | J19: Left own eat wife tell with. | K19: =IF(COUNTIF(Customers!A:A, H19)>0, "Valid", "Invalid") -> Valid | L19: =TEXT(B19,"m") -> 6 | M19: =TEXT(B19,"yyyy") -> 2022 | N19: =IF(D19="Revenue",C19,-ABS(C19)) -> 107495.7 | O19: =IF(D19="Revenue", C19, "") -> 107495.7 | P19: =IF(D19="Expense", ABS(C19), "") | Q19: =IF(O19="","", IF(OR(O19<EDA_Outlier_Analysis!$C$10, O19>EDA_Outlier_Analysis!$C$11), "Outlier", "Normal")) -> Normal | R19: =IF(P19="","", IF(OR(P19 < EDA_Outlier_Analysis!$F$7, P19 > EDA_Outlier_Analysis!$F$8), "Outlier", "Normal")) | S19: =IF(N19="","", IF(OR(N19 <EDA_Outlier_Analysis!$I$10, N19 > EDA_Outlier_Analysis!$I$11), "Outlier", "Normal")) -> Normal
A20: TRX100018 | B20: 45190 | C20: 83127.62 | D20: Revenue | E20: Subscription | F20: Online | G20: West | H20: CUST10333 | J20: Individual first region. | K20: =IF(COUNTIF(Customers!A:A, H20)>0, "Valid", "Invalid") -> Valid | L20: =TEXT(B20,"m") -> 9 | M20: =TEXT(B20,"yyyy") -> 2023 | N20: =IF(D20="Revenue",C20,-ABS(C20)) -> 83127.62 | O20: =IF(D20="Revenue", C20, "") -> 83127.62 | P20: =IF(D20="Expense", ABS(C20), "") | Q20: =IF(O20="","", IF(OR(O20<EDA_Outlier_Analysis!$C$10, O20>EDA_Outlier_Analysis!$C$11), "Outlier", "Normal")) -> Normal | R20: =IF(P20="","", IF(OR(P20 < EDA_Outlier_Analysis!$F$7, P20 > EDA_Outlier_Analysis!$F$8), "Outlier", "Normal")) | S20: =IF(N20="","", IF(OR(N20 <EDA_Outlier_Analysis!$I$10, N20 > EDA_Outlier_Analysis!$I$11), "Outlier", "Normal")) -> Normal
A21: TRX100019 | B21: 44793 | C21: 145634.47 | D21: Revenue | E21: Service | F21: Enterprise | G21: West | H21: CUST10302 | J21: Rise war shake doctor. | K21: =IF(COUNTIF(Customers!A:A, H21)>0, "Valid", "Invalid") -> Valid | L21: =TEXT(B21,"m") -> 8 | M21: =TEXT(B21,"yyyy") -> 2022 | N21: =IF(D21="Revenue",C21,-ABS(C21)) -> 145634.47 | O21: =IF(D21="Revenue", C21, "") -> 145634.47 | P21: =IF(D21="Expense", ABS(C21), "") | Q21: =IF(O21="","", IF(OR(O21<EDA_Outlier_Analysis!$C$10, O21>EDA_Outlier_Analysis!$C$11), "Outlier", "Normal")) -> Normal | R21: =IF(P21="","", IF(OR(P21 < EDA_Outlier_Analysis!$F$7, P21 > EDA_Outlier_Analysis!$F$8), "Outlier", "Normal")) | S21: =IF(N21="","", IF(OR(N21 <EDA_Outlier_Analysis!$I$10, N21 > EDA_Outlier_Analysis!$I$11), "Outlier", "Normal")) -> Normal
A22: TRX100020 | B22: 45062 | C22: 167566.97 | D22: Revenue | E22: Service | F22: Retail | G22: North | H22: CUST10042 | J22: Before expect allow job one set. | K22: =IF(COUNTIF(Customers!A:A, H22)>0, "Valid", "Invalid") -> Valid | L22: =TEXT(B22,"m") -> 5 | M22: =TEXT(B22,"yyyy") -> 2023 | N22: =IF(D22="Revenue",C22,-ABS(C22)) -> 167566.97 | O22: =IF(D22="Revenue", C22, "") -> 167566.97 | P22: =IF(D22="Expense", ABS(C22), "") | Q22: =IF(O22="","", IF(OR(O22<EDA_Outlier_Analysis!$C$10, O22>EDA_Outlier_Analysis!$C$11), "Outlier", "Normal")) -> Normal | R22: =IF(P22="","", IF(OR(P22 < EDA_Outlier_Analysis!$F$7, P22 > EDA_Outlier_Analysis!$F$8), "Outlier", "Normal")) | S22: =IF(N22="","", IF(OR(N22 <EDA_Outlier_Analysis!$I$10, N22 > EDA_Outlier_Analysis!$I$11), "Outlier", "Normal")) -> Normal
A23: TRX100021 | B23: 44726 | C23: -2000 | D23: Expense | E23: Rent | F23: Online | G23: West | I23: VEND1022 | J23: Side official leave seem financial. | K23: =IF(COUNTIF(Customers!A:A, H23)>0, "Valid", "Invalid") -> Invalid | L23: =TEXT(B23,"m") -> 6 | M23: =TEXT(B23,"yyyy") -> 2022 | N23: =IF(D23="Revenue",C23,-ABS(C23)) -> -2000 | O23: =IF(D23="Revenue", C23, "") | P23: =IF(D23="Expense", ABS(C23), "") -> 2000 | Q23: =IF(O23="","", IF(OR(O23<EDA_Outlier_Analysis!$C$10, O23>EDA_Outlier_Analysis!$C$11), "Outlier", "Normal")) | R23: =IF(P23="","", IF(OR(P23 < EDA_Outlier_Analysis!$F$7, P23 > EDA_Outlier_Analysis!$F$8), "Outlier", "Normal")) -> Outlier | S23: =IF(N23="","", IF(OR(N23 <EDA_Outlier_Analysis!$I$10, N23 > EDA_Outlier_Analysis!$I$11), "Outlier", "Normal")) -> Normal
A24: TRX100022 | B24: 44998 | C24: 203374.65 | D24: Revenue | E24: Service | F24: Online | G24: South | H24: CUST10021 | J24: Must require bit relate Congress local improve organization. | K24: =IF(COUNTIF(Customers!A:A, H24)>0, "Valid", "Invalid") -> Valid | L24: =TEXT(B24,"m") -> 3 | M24: =TEXT(B24,"yyyy") -> 2023 | N24: =IF(D24="Revenue",C24,-ABS(C24)) -> 203374.65 | O24: =IF(D24="Revenue", C24, "") -> 203374.65 | P24: =IF(D24="Expense", ABS(C24), "") | Q24: =IF(O24="","", IF(OR(O24<EDA_Outlier_Analysis!$C$10, O24>EDA_Outlier_Analysis!$C$11), "Outlier", "Normal")) -> Normal | R24: =IF(P24="","", IF(OR(P24 < EDA_Outlier_Analysis!$F$7, P24 > EDA_Outlier_Analysis!$F$8), "Outlier", "Normal")) | S24: =IF(N24="","", IF(OR(N24 <EDA_Outlier_Analysis!$I$10, N24 > EDA_Outlier_Analysis!$I$11), "Outlier", "Normal")) -> Normal
A25: TRX100023 | B25: 45189 | C25: 171433.19 | D25: Revenue | E25: Product | F25: Enterprise | G25: West | H25: CUST10218 | J25: Identify loss across fact government sea upon. | K25: =IF(COUNTIF(Customers!A:A, H25)>0, "Valid", "Invalid") -> Valid | L25: =TEXT(B25,"m") -> 9 | M25: =TEXT(B25,"yyyy") -> 2023 | N25: =IF(D25="Revenue",C25,-ABS(C25)) -> 171433.19 | O25: =IF(D25="Revenue", C25, "") -> 171433.19 | P25: =IF(D25="Expense", ABS(C25), "") | Q25: =IF(O25="","", IF(OR(O25<EDA_Outlier_Analysis!$C$10, O25>EDA_Outlier_Analysis!$C$11), "Outlier", "Normal")) -> Normal | R25: =IF(P25="","", IF(OR(P25 < EDA_Outlier_Analysis!$F$7, P25 > EDA_Outlier_Analysis!$F$8), "Outlier", "Normal")) | S25: =IF(N25="","", IF(OR(N25 <EDA_Outlier_Analysis!$I$10, N25 > EDA_Outlier_Analysis!$I$11), "Outlier", "Normal")) -> Normal
A26: TRX100024 | B26: 44850 | C26: -60198.87 | D26: Expense | E26: Payroll | F26: Enterprise | G26: North | I26: VEND1058 | J26: Big fine cause full reality heart condition another. | K26: =IF(COUNTIF(Customers!A:A, H26)>0, "Valid", "Invalid") -> Invalid | L26: =TEXT(B26,"m") -> 10 | M26: =TEXT(B26,"yyyy") -> 2022 | N26: =IF(D26="Revenue",C26,-ABS(C26)) -> -60198.87 | O26: =IF(D26="Revenue", C26, "") | P26: =IF(D26="Expense", ABS(C26), "") -> 60198.87 | Q26: =IF(O26="","", IF(OR(O26<EDA_Outlier_Analysis!$C$10, O26>EDA_Outlier_Analysis!$C$11), "Outlier", "Normal")) | R26: =IF(P26="","", IF(OR(P26 < EDA_Outlier_Analysis!$F$7, P26 > EDA_Outlier_Analysis!$F$8), "Outlier", "Normal")) -> Outlier | S26: =IF(N26="","", IF(OR(N26 <EDA_Outlier_Analysis!$I$10, N26 > EDA_Outlier_Analysis!$I$11), "Outlier", "Normal")) -> Normal
A27: TRX100025 | B27: 45097 | C27: -40143.88 | D27: Expense | E27: Rent | F27: Retail | G27: West | I27: VEND1037 | J27: Good owner financial any result summer physical. | K27: =IF(COUNTIF(Customers!A:A, H27)>0, "Valid", "Invalid") -> Invalid | L27: =TEXT(B27,"m") -> 6 | M27: =TEXT(B27,"yyyy") -> 2023 | N27: =IF(D27="Revenue",C27,-ABS(C27)) -> -40143.88 | O27: =IF(D27="Revenue", C27, "") | P27: =IF(D27="Expense", ABS(C27), "") -> 40143.88 | Q27: =IF(O27="","", IF(OR(O27<EDA_Outlier_Analysis!$C$10, O27>EDA_Outlier_Analysis!$C$11), "Outlier", "Normal")) | R27: =IF(P27="","", IF(OR(P27 < EDA_Outlier_Analysis!$F$7, P27 > EDA_Outlier_Analysis!$F$8), "Outlier", "Normal")) -> Normal | S27: =IF(N27="","", IF(OR(N27 <EDA_Outlier_Analysis!$I$10, N27 > EDA_Outlier_Analysis!$I$11), "Outlier", "Normal")) -> Normal
A28: TRX100026 | B28: 45208 | C28: -38329 | D28: Expense | E28: Marketing | F28: Enterprise | G28: West | I28: VEND1049 | J28: Sport note decide who modern car knowledge. | K28: =IF(COUNTIF(Customers!A:A, H28)>0, "Valid", "Invalid") -> Invalid | L28: =TEXT(B28,"m") -> 10 | M28: =TEXT(B28,"yyyy") -> 2023 | N28: =IF(D28="Revenue",C28,-ABS(C28)) -> -38329 | O28: =IF(D28="Revenue", C28, "") | P28: =IF(D28="Expense", ABS(C28), "") -> 38329 | Q28: =IF(O28="","", IF(OR(O28<EDA_Outlier_Analysis!$C$10, O28>EDA_Outlier_Analysis!$C$11), "Outlier", "Normal")) | R28: =IF(P28="","", IF(OR(P28 < EDA_Outlier_Analysis!$F$7, P28 > EDA_Outlier_Analysis!$F$8), "Outlier", "Normal")) -> Normal | S28: =IF(N28="","", IF(OR(N28 <EDA_Outlier_Analysis!$I$10, N28 > EDA_Outlier_Analysis!$I$11), "Outlier", "Normal")) -> Normal
A29: TRX100027 | B29: 44901 | C29: 193475.45 | D29: Revenue | E29: Service | F29: Retail | G29: South | H29: CUST10146 | J29: Game step assume late home order morning to. | K29: =IF(COUNTIF(Customers!A:A, H29)>0, "Valid", "Invalid") -> Valid | L29: =TEXT(B29,"m") -> 12 | M29: =TEXT(B29,"yyyy") -> 2022 | N29: =IF(D29="Revenue",C29,-ABS(C29)) -> 193475.45 | O29: =IF(D29="Revenue", C29, "") -> 193475.45 | P29: =IF(D29="Expense", ABS(C29), "") | Q29: =IF(O29="","", IF(OR(O29<EDA_Outlier_Analysis!$C$10, O29>EDA_Outlier_Analysis!$C$11), "Outlier", "Normal")) -> Normal | R29: =IF(P29="","", IF(OR(P29 < EDA_Outlier_Analysis!$F$7, P29 > EDA_Outlier_Analysis!$F$8), "Outlier", "Normal")) | S29: =IF(N29="","", IF(OR(N29 <EDA_Outlier_Analysis!$I$10, N29 > EDA_Outlier_Analysis!$I$11), "Outlier", "Normal")) -> Normal
A30: TRX100028 | B30: 45002 | C30: 139672.98 | D30: Revenue | E30: Subscription | F30: Enterprise | G30: South | H30: CUST10074 | J30: Nature need environment operation country easy across choice. | K30: =IF(COUNTIF(Customers!A:A, H30)>0, "Valid", "Invalid") -> Valid | L30: =TEXT(B30,"m") -> 3 | M30: =TEXT(B30,"yyyy") -> 2023 | N30: =IF(D30="Revenue",C30,-ABS(C30)) -> 139672.98 | O30: =IF(D30="Revenue", C30, "") -> 139672.98 | P30: =IF(D30="Expense", ABS(C30), "") | Q30: =IF(O30="","", IF(OR(O30<EDA_Outlier_Analysis!$C$10, O30>EDA_Outlier_Analysis!$C$11), "Outlier", "Normal")) -> Normal | R30: =IF(P30="","", IF(OR(P30 < EDA_Outlier_Analysis!$F$7, P30 > EDA_Outlier_Analysis!$F$8), "Outlier", "Normal")) | S30: =IF(N30="","", IF(OR(N30 <EDA_Outlier_Analysis!$I$10, N30 > EDA_Outlier_Analysis!$I$11), "Outlier", "Normal")) -> Normal
A31: TRX100029 | B31: 45188 | C31: 198385.78 | D31: Revenue | E31: Subscription | F31: Enterprise | G31: North | H31: CUST10011 | J31: Scientist particularly include true listen happy. | K31: =IF(COUNTIF(Customers!A:A, H31)>0, "Valid", "Invalid") -> Valid | L31: =TEXT(B31,"m") -> 9 | M31: =TEXT(B31,"yyyy") -> 2023 | N31: =IF(D31="Revenue",C31,-ABS(C31)) -> 198385.78 | O31: =IF(D31="Revenue", C31, "") -> 198385.78 | P31: =IF(D31="Expense", ABS(C31), "") | Q31: =IF(O31="","", IF(OR(O31<EDA_Outlier_Analysis!$C$10, O31>EDA_Outlier_Analysis!$C$11), "Outlier", "Normal")) -> Normal | R31: =IF(P31="","", IF(OR(P31 < EDA_Outlier_Analysis!$F$7, P31 > EDA_Outlier_Analysis!$F$8), "Outlier", "Normal")) | S31: =IF(N31="","", IF(OR(N31 <EDA_Outlier_Analysis!$I$10, N31 > EDA_Outlier_Analysis!$I$11), "Outlier", "Normal")) -> Normal
A32: TRX100030 | B32: 44814 | C32: 137108.16 | D32: Revenue | E32: Service | F32: Enterprise | G32: East | H32: CUST10325 | J32: Citizen help never simple course. | K32: =IF(COUNTIF(Customers!A:A, H32)>0, "Valid", "Invalid") -> Valid | L32: =TEXT(B32,"m") -> 9 | M32: =TEXT(B32,"yyyy") -> 2022 | N32: =IF(D32="Revenue",C32,-ABS(C32)) -> 137108.16 | O32: =IF(D32="Revenue", C32, "") -> 137108.16 | P32: =IF(D32="Expense", ABS(C32), "") | Q32: =IF(O32="","", IF(OR(O32<EDA_Outlier_Analysis!$C$10, O32>EDA_Outlier_Analysis!$C$11), "Outlier", "Normal")) -> Normal | R32: =IF(P32="","", IF(OR(P32 < EDA_Outlier_Analysis!$F$7, P32 > EDA_Outlier_Analysis!$F$8), "Outlier", "Normal")) | S32: =IF(N32="","", IF(OR(N32 <EDA_Outlier_Analysis!$I$10, N32 > EDA_Outlier_Analysis!$I$11), "Outlier", "Normal")) -> Normal
A33: TRX100031 | B33: 44624 | C33: -44326.21 | D33: Expense | E33: Other | F33: Retail | G33: East | I33: VEND1053 | J33: Billion newspaper modern fine career somebody. | K33: =IF(COUNTIF(Customers!A:A, H33)>0, "Valid", "Invalid") -> Invalid | L33: =TEXT(B33,"m") -> 3 | M33: =TEXT(B33,"yyyy") -> 2022 | N33: =IF(D33="Revenue",C33,-ABS(C33)) -> -44326.21 | O33: =IF(D33="Revenue", C33, "") | P33: =IF(D33="Expense", ABS(C33), "") -> 44326.21 | Q33: =IF(O33="","", IF(OR(O33<EDA_Outlier_Analysis!$C$10, O33>EDA_Outlier_Analysis!$C$11), "Outlier", "Normal")) | R33: =IF(P33="","", IF(OR(P33 < EDA_Outlier_Analysis!$F$7, P33 > EDA_Outlier_Analysis!$F$8), "Outlier", "Normal")) -> Normal | S33: =IF(N33="","", IF(OR(N33 <EDA_Outlier_Analysis!$I$10, N33 > EDA_Outlier_Analysis!$I$11), "Outlier", "Normal")) -> Normal
A34: TRX100032 | B34: 44970 | C34: 162088.99 | D34: Revenue | E34: Service | F34: Enterprise | G34: North | H34: CUST10203 | J34: Wall campaign might anyone. | K34: =IF(COUNTIF(Customers!A:A, H34)>0, "Valid", "Invalid") -> Valid | L34: =TEXT(B34,"m") -> 2 | M34: =TEXT(B34,"yyyy") -> 2023 | N34: =IF(D34="Revenue",C34,-ABS(C34)) -> 162088.99 | O34: =IF(D34="Revenue", C34, "") -> 162088.99 | P34: =IF(D34="Expense", ABS(C34), "") | Q34: =IF(O34="","", IF(OR(O34<EDA_Outlier_Analysis!$C$10, O34>EDA_Outlier_Analysis!$C$11), "Outlier", "Normal")) -> Normal | R34: =IF(P34="","", IF(OR(P34 < EDA_Outlier_Analysis!$F$7, P34 > EDA_Outlier_Analysis!$F$8), "Outlier", "Normal")) | S34: =IF(N34="","", IF(OR(N34 <EDA_Outlier_Analysis!$I$10, N34 > EDA_Outlier_Analysis!$I$11), "Outlier", "Normal")) -> Normal
A35: TRX100033 | B35: 44847 | C35: 138103.68 | D35: Revenue | E35: Subscription | F35: Online | G35: North | H35: CUST10151 | J35: Could impact decide key. | K35: =IF(COUNTIF(Customers!A:A, H35)>0, "Valid", "Invalid") -> Valid | L35: =TEXT(B35,"m") -> 10 | M35: =TEXT(B35,"yyyy") -> 2022 | N35: =IF(D35="Revenue",C35,-ABS(C35)) -> 138103.68 | O35: =IF(D35="Revenue", C35, "") -> 138103.68 | P35: =IF(D35="Expense", ABS(C35), "") | Q35: =IF(O35="","", IF(OR(O35<EDA_Outlier_Analysis!$C$10, O35>EDA_Outlier_Analysis!$C$11), "Outlier", "Normal")) -> Normal | R35: =IF(P35="","", IF(OR(P35 < EDA_Outlier_Analysis!$F$7, P35 > EDA_Outlier_Analysis!$F$8), "Outlier", "Normal")) | S35: =IF(N35="","", IF(OR(N35 <EDA_Outlier_Analysis!$I$10, N35 > EDA_Outlier_Analysis!$I$11), "Outlier", "Normal")) -> Normal
A36: TRX100034 | B36: 44695 | C36: -10197.61 | D36: Expense | E36: Utilities | F36: Retail | G36: East | I36: VEND1014 | J36: Imagine must who discover since painting. | K36: =IF(COUNTIF(Customers!A:A, H36)>0, "Valid", "Invalid") -> Invalid | L36: =TEXT(B36,"m") -> 5 | M36: =TEXT(B36,"yyyy") -> 2022 | N36: =IF(D36="Revenue",C36,-ABS(C36)) -> -10197.61 | O36: =IF(D36="Revenue", C36, "") | P36: =IF(D36="Expense", ABS(C36), "") -> 10197.61 | Q36: =IF(O36="","", IF(OR(O36<EDA_Outlier_Analysis!$C$10, O36>EDA_Outlier_Analysis!$C$11), "Outlier", "Normal")) | R36: =IF(P36="","", IF(OR(P36 < EDA_Outlier_Analysis!$F$7, P36 > EDA_Outlier_Analysis!$F$8), "Outlier", "Normal")) -> Outlier | S36: =IF(N36="","", IF(OR(N36 <EDA_Outlier_Analysis!$I$10, N36 > EDA_Outlier_Analysis!$I$11), "Outlier", "Normal")) -> Normal
A37: TRX100035 | B37: 45145 | C37: -62926.94 | D37: Expense | E37: Marketing | F37: Retail | G37: West | I37: VEND1093 | J37: Training nor arrive. | K37: =IF(COUNTIF(Customers!A:A, H37)>0, "Valid", "Invalid") -> Invalid | L37: =TEXT(B37,"m") -> 8 | M37: =TEXT(B37,"yyyy") -> 2023 | N37: =IF(D37="Revenue",C37,-ABS(C37)) -> -62926.94 | O37: =IF(D37="Revenue", C37, "") | P37: =IF(D37="Expense", ABS(C37), "") -> 62926.94 | Q37: =IF(O37="","", IF(OR(O37<EDA_Outlier_Analysis!$C$10, O37>EDA_Outlier_Analysis!$C$11), "Outlier", "Normal")) | R37: =IF(P37="","", IF(OR(P37 < EDA_Outlier_Analysis!$F$7, P37 > EDA_Outlier_Analysis!$F$8), "Outlier", "Normal")) -> Outlier | S37: =IF(N37="","", IF(OR(N37 <EDA_Outlier_Analysis!$I$10, N37 > EDA_Outlier_Analysis!$I$11), "Outlier", "Normal")) -> Normal
A38: TRX100036 | B38: 45195 | C38: 144593.87 | D38: Revenue | E38: Service | F38: Enterprise | G38: East | H38: CUST10086 | J38: Field some arrive society everybody guy public. | K38: =IF(COUNTIF(Customers!A:A, H38)>0, "Valid", "Invalid") -> Valid | L38: =TEXT(B38,"m") -> 9 | M38: =TEXT(B38,"yyyy") -> 2023 | N38: =IF(D38="Revenue",C38,-ABS(C38)) -> 144593.87 | O38: =IF(D38="Revenue", C38, "") -> 144593.87 | P38: =IF(D38="Expense", ABS(C38), "") | Q38: =IF(O38="","", IF(OR(O38<EDA_Outlier_Analysis!$C$10, O38>EDA_Outlier_Analysis!$C$11), "Outlier", "Normal")) -> Normal | R38: =IF(P38="","", IF(OR(P38 < EDA_Outlier_Analysis!$F$7, P38 > EDA_Outlier_Analysis!$F$8), "Outlier", "Normal")) | S38: =IF(N38="","", IF(OR(N38 <EDA_Outlier_Analysis!$I$10, N38 > EDA_Outlier_Analysis!$I$11), "Outlier", "Normal")) -> Normal
A39: TRX100037 | B39: 44595 | C39: 38814.58 | D39: Revenue | E39: Product | F39: Retail | G39: North | H39: CUST10013 | J39: Order agreement mind everything. | K39: =IF(COUNTIF(Customers!A:A, H39)>0, "Valid", "Invalid") -> Valid | L39: =TEXT(B39,"m") -> 2 | M39: =TEXT(B39,"yyyy") -> 2022 | N39: =IF(D39="Revenue",C39,-ABS(C39)) -> 38814.58 | O39: =IF(D39="Revenue", C39, "") -> 38814.58 | P39: =IF(D39="Expense", ABS(C39), "") | Q39: =IF(O39="","", IF(OR(O39<EDA_Outlier_Analysis!$C$10, O39>EDA_Outlier_Analysis!$C$11), "Outlier", "Normal")) -> Normal | R39: =IF(P39="","", IF(OR(P39 < EDA_Outlier_Analysis!$F$7, P39 > EDA_Outlier_Analysis!$F$8), "Outlier", "Normal")) | S39: =IF(N39="","", IF(OR(N39 <EDA_Outlier_Analysis!$I$10, N39 > EDA_Outlier_Analysis!$I$11), "Outlier", "Normal")) -> Normal
A40: TRX100038 | B40: 44983 | C40: -36977.97 | D40: Expense | E40: Rent | F40: Online | G40: East | I40: VEND1082 | J40: Watch would miss interview water trouble. | K40: =IF(COUNTIF(Customers!A:A, H40)>0, "Valid", "Invalid") -> Invalid | L40: =TEXT(B40,"m") -> 2 | M40: =TEXT(B40,"yyyy") -> 2023 | N40: =IF(D40="Revenue",C40,-ABS(C40)) -> -36977.97 | O40: =IF(D40="Revenue", C40, "") | P40: =IF(D40="Expense", ABS(C40), "") -> 36977.97 | Q40: =IF(O40="","", IF(OR(O40<EDA_Outlier_Analysis!$C$10, O40>EDA_Outlier_Analysis!$C$11), "Outlier", "Normal")) | R40: =IF(P40="","", IF(OR(P40 < EDA_Outlier_Analysis!$F$7, P40 > EDA_Outlier_Analysis!$F$8), "Outlier", "Normal")) -> Normal | S40: =IF(N40="","", IF(OR(N40 <EDA_Outlier_Analysis!$I$10, N40 > EDA_Outlier_Analysis!$I$11), "Outlier", "Normal")) -> Normal
...

Sheet Headcount
A1: employee_id | B1: employee_name | C1: business_unit | D1: join_date | E1: status | F1: region | G1: cost_to_company
A2: EMP1000 | B2: Daniel Thornton | C2: Enterprise | D2: 44968 | E2: Active | F2: South | G2: 1566441
A3: EMP1001 | B3: Ashley Burch | C3: Retail | D3: 44084 | E3: Active | F3: West | G3: 1533942
A4: EMP1002 | B4: Angel Perry | C4: Online | D4: 44620 | E4: Active | F4: East | G4: 962333
A5: EMP1003 | B5: Kimberly Harmon | C5: Online | D5: 44484 | E5: Active | F5: North | G5: 503403
A6: EMP1004 | B6: Sarah Smith DDS | C6: Enterprise | D6: 44957 | E6: Active | F6: West | G6: 1051271
A7: EMP1005 | B7: Sierra Jordan | C7: Enterprise | D7: 44945 | E7: Active | F7: South | G7: 731473
A8: EMP1006 | B8: Adam Wood | C8: Enterprise | D8: 43768 | E8: Active | F8: West | G8: 596883
A9: EMP1007 | B9: Keith Collins | C9: Online | D9: 44993 | E9: Active | F9: East | G9: 864597
A10: EMP1008 | B10: Mitchell Kelly | C10: Enterprise | D10: 44438 | E10: Active | F10: North | G10: 1736454
A11: EMP1009 | B11: Jacob Mendez | C11: Enterprise | D11: 45166 | E11: Active | F11: North | G11: 1479884
A12: EMP1010 | B12: William Bryant | C12: Enterprise | D12: 44563 | E12: Active | F12: North | G12: 1160373
A13: EMP1011 | B13: Sean Daniels | C13: Retail | D13: 44741 | E13: Active | F13: South | G13: 1603487
... A201: EMP1199 | B201: Mr. Alec Nelson | C201: Enterprise | D201: 44808 | E201: Inactive | F201: South | G201: 728593

Sheet Vendors
A1: vendor_id | B1: vendor_name | C1: category | D1: region | E1: active
A2: VEND1000 | B2: Johnson-Howard | C2: Supplies | D2: East | E2: Y
A3: VEND1001 | B3: Jensen Ltd | C3: Consulting | D3: South | E3: Y
A4: VEND1002 | B4: Collins Group | C4: Services | D4: North | E4: Y
A5: VEND1003 | B5: Smith, Kirby and Torres | C5: Utilities | D5: North | E5: Y
A6: VEND1004 | B6: Mcgrath, Wheeler and Boyd | C6: Utilities | D6: North | E6: Y
A7: VEND1005 | B7: Cooper-Larson | C7: Supplies | D7: South | E7: Y
A8: VEND1006 | B8: Ward-David | C8: Utilities | D8: South | E8: Y
A9: VEND1007 | B9: Savage Ltd | C9: Utilities | D9: West | E9: Y
A10: VEND1008 | B10: Medina-Lee | C10: Services | D10: South | E10: Y
A11: VEND1009 | B11: Griffith and Sons | C11: Services | D11: East | E11: Y
A12: VEND1010 | B12: Thomas-Santana | C12: Rent | D12: South | E12: Y
... A121: VEND1119 | B121: Graham-Lopez | C121: Consulting | D121: North | E121: N

Sheet EDA_Overview
A1: Datasets
A3: Financial_transactions | B3: Row Count | C3: Total Unique transaction IDs | D3: Start Year | E3: End Year | F3: Business Units | G3: Category
B4: =COUNTA(Financial_Transactions!A2:A10401) -> 10400 | C4: =COUNTA(_xlfn.UNIQUE(Financial_Transactions!A2:A10401)) -> 10400 | D4: =YEAR(MIN(Financial_Transactions!B:B)) -> 2022 | E4: =YEAR(MAX(Financial_Transactions!B:B)) -> 2023 | F4: =_xlfn.TEXTJOIN(", ", TRUE, _xlfn.UNIQUE(Financial_Transactions!F2:F10400)) -> Online, Enterprise, Retail | G4: =_xlfn.TEXTJOIN(", ", TRUE, _xlfn.UNIQUE(Financial_Transactions!E2:E10400)) -> Supplies, Utilities, Subscription, Service, Rent, Marketing, Product, Equity, Other, Payroll, Asset, Liability
A6: Customers | B6: Total customer_ids | C6: Business Segments
B7: =COUNTA(_xlfn.UNIQUE(Customers!A2:A401)) -> 400 | C7: =_xlfn.TEXTJOIN(",",TRUE,_xlfn.UNIQUE(Customers!C2:C401)) -> Online,Enterprise,Retail
A9: Headcount | B9: Total Unique employee_id
B10: =COUNTA(_xlfn.UNIQUE(Headcount!A2:A201)) -> 200
A12: Vendor | B12: Total Unique Vendor_id
B13: =COUNTA(_xlfn.UNIQUE(Vendors!A2:A121)) -> 120
A14: Budget | B14: Key Info
B15: Covers 2022–2023, aligned to all business units
A17: Key points to note
A18: Data spans 2022–2023 with complete monthly coverage
A19: All business units are present across datasets
A20: No missing business units in budget or headcount data
A21: Customer and vendor foreign keys were validated during KPI computation

Sheet EDA_Descriptive_Stats
D1: EXPLORATORY DATA ANALYSIS (EDA) – DESCRIPTIVE STATISTICS
A4: Objective: Summarize key financial KPIs using statistical measures to understand distribution, variability, and trends.
A6: REVENUE – DESCRIPTIVE STATISTICS | E6: EXPENSE – DESCRIPTIVE STATISTICS | H6: PROFIT – DESCRIPTIVE STATISTICS | L6: BUDGET VARIANCE - DESCRIPTIVE STATISTICS
A8: Statistic | B8: Revenue | E8: Statistic | F8: Expense | H8: Statistic | I8: Profit | L8: Statistic | M8: Budget Variance
A9: Mean | B9: =AVERAGEIFS(Financial_Transactions!C:C,Financial_Transactions!D:D,"Revenue") -> 156802.43 | E9: Mean | F9: =ABS(AVERAGEIFS(Financial_Transactions!C:C,Financial_Transactions!D:D,"Expense")) -> 40664.558 | H9: Mean | I9: =AVERAGE(Financial_Transactions!N:N) -> 65556.264 | L9: Mean | M9: =AVERAGE(Budget!H2:H73) -> 8440057.9
A10: Median | B10: {=MEDIAN(_xlfn._xlws.FILTER(Financial_Transactions!C:C, Financial_Transactions!D:D="Revenue"))} -> 153910.43 | E10: Median | F10: {=ABS(MEDIAN(_xlfn._xlws.FILTER(Financial_Transactions!C:C, Financial_Transactions!D:D="Expense")))} -> 40510.71 | H10: Median | I10: =MEDIAN(Financial_Transactions!N:N) -> 78624.65 | L10: Median | M10: =MEDIAN(Budget!H2:H73) -> 8194659.6
A11: Minimum | B11: {=MIN(_xlfn._xlws.FILTER(Financial_Transactions!C:C, Financial_Transactions!D:D="Revenue"))} -> 5000 | E11: Minimum | F11: {=ABS(MIN(_xlfn._xlws.FILTER(Financial_Transactions!C:C, Financial_Transactions!D:D="Expense")))} -> 113310.71 | H11: Minimum | I11: =MIN(Financial_Transactions!N:N) -> -113310.71 | L11: Minimum | M11: =MIN(Budget!H2:H73) -> 3250588.4
A12: Maximum | B12: {=MAX(_xlfn._xlws.FILTER(Financial_Transactions!C:C, Financial_Transactions!D:D="Revenue"))} -> 351386.85 | E12: Maximum | F12: {=ABS(MAX(_xlfn._xlws.FILTER(Financial_Transactions!C:C, Financial_Transactions!D:D="Expense")))} -> 2000 | H12: Maximum | I12: =MAX(Financial_Transactions!N:N) -> 351386.85 | L12: Maximum | M12: =MAX(Budget!H2:H73) -> 15209080
A13: Standard Deviation | B13: {=_xlfn.STDEV.P(_xlfn._xlws.FILTER(Financial_Transactions!C:C, Financial_Transactions!D:D="Revenue"))} -> 51985.266 | E13: Standard Deviation | F13: {=_xlfn.STDEV.P(_xlfn._xlws.FILTER(Financial_Transactions!C:C, Financial_Transactions!D:D="Expense"))} -> 19230.595 | H13: Standard Deviation | I13: =_xlfn.STDEV.P(Financial_Transactions!N:N) -> 104905.64 | L13: Standard Deviation | M13: =_xlfn.STDEV.P(Budget!H2:H73) -> 2793340.2
A14: Interquartile Range (IQR) | B14: {=_xlfn.QUARTILE.INC(_xlfn._xlws.FILTER(Financial_Transactions!C:C, Financial_Transactions!D:D="Revenue"),3)-_xlfn.QUARTILE.INC(_xlfn._xlws.FILTER(Financial_Transactions!C:C, Financial_Transactions!D:D="Revenue"),1)} -> 69004.928 | E14: Interquartile Range (IQR) | F14: {=_xlfn.QUARTILE.INC(_xlfn._xlws.FILTER(Financial_Transactions!C:C, Financial_Transactions!D:D="Expense"),3)-_xlfn.QUARTILE.INC(_xlfn._xlws.FILTER(Financial_Transactions!C:C, Financial_Transactions!D:D="Expense"),1)} -> 26511.16 | H14: Interquartile Range (IQR) | I14: =_xlfn.QUARTILE.INC(Financial_Transactions!N:N,3)-_xlfn.QUARTILE.INC(Financial_Transactions!N:N,1) -> 191115.76 | L14: Interquartile Range (IQR) | M14: =_xlfn.QUARTILE.INC(Budget!H2:H73,3)-_xlfn.QUARTILE.INC(Budget!H2:H73,1) -> 3731206.1
E15: Note use ABS IF WANT THE VALUE IN +
A17: KEY OBSERVATIONS
A18: Revenue | E18: Expense | H18: Profit | L18: Budget Variance
A19: Mean revenue is higher than median → right-skewed distribution | E19: Expense distribution is stable across months | H19: High variance indicates fluctuating profitability | L19: Majority of values positive → frequent over-budget instances
A20: Presence of high-value outlier | E20: Low IQR indicates controlled spending | H20: Some negative profit periods observed | L20: Large variance in Enterprise unit

Sheet KPI
D1: FINANCIAL PERFORMANCE ANALYSIS – KPI DASHBOARD
J4: BUDGET VARIANCE KPI
A5: REVENUE & EXPENSE KPI | F5: PROFIT KPI
J6: Year | K6: Business Unit | L6: Actual Expense | M6: Budgeted Expense | N6: Budget Variance
A7: Year | B7: Business Unit | C7: Revenue | D7: Expense | J7: 2023 | K7: Enterprise | L7: =ABS(SUMIFS(Financial_Transactions!C:C,Financial_Transactions!D:D,"Expense",Financial_Transactions!M:M,KPI!J7,Financial_Transactions!F:F,KPI!K7)) -> 28998688 | M7: =SUMIFS( Budget!E:E, Budget!C:C, KPI!K7, Budget!A:A, KPI!J7 ) -> 17612412 | N7: =L7-M7 -> 11386276
A8: 2023 | B8: Enterprise | C8: =SUMIFS(Financial_Transactions!C:C,Financial_Transactions!D:D,"Revenue",Financial_Transactions!M:M,KPI!A8,Financial_Transactions!F:F,KPI!B8) -> 1.6433538e+08 | D8: =ABS(SUMIFS(Financial_Transactions!C:C,Financial_Transactions!D:D,"Expense",Financial_Transactions!M:M,KPI!A8,Financial_Transactions!F:F,KPI!B8)) -> 28998688 | F8: =SUMIFS(Financial_Transactions!C:C,Financial_Transactions!D:D,"Revenue",Financial_Transactions!K:K,"Valid")-SUMIFS(Financial_Transactions!C:C,Financial_Transactions!D:D,"Expense",Financial_Transactions!K:K,"Valid") -> 8.6460859e+08 | J8: 2023 | K8: Retail | L8: =ABS(SUMIFS(Financial_Transactions!C:C,Financial_Transactions!D:D,"Expense",Financial_Transactions!M:M,KPI!J8,Financial_Transactions!F:F,KPI!K8)) -> 27443202 | M8: =SUMIFS( Budget!E:E, Budget!C:C, KPI!K8, Budget!A:A, KPI!J8 ) -> 15792087 | N8: =L8-M8 -> 11651115
A9: 2023 | B9: Retail | C9: =SUMIFS(Financial_Transactions!C:C,Financial_Transactions!D:D,"Revenue",Financial_Transactions!M:M,KPI!A9,Financial_Transactions!F:F,KPI!B9) -> 1.5615796e+08 | D9: =ABS(SUMIFS(Financial_Transactions!C:C,Financial_Transactions!D:D,"Expense",Financial_Transactions!M:M,KPI!A9,Financial_Transactions!F:F,KPI!B9)) -> 27443202 | J9: 2023 | K9: Online | L9: =ABS(SUMIFS(Financial_Transactions!C:C,Financial_Transactions!D:D,"Expense",Financial_Transactions!M:M,KPI!J9,Financial_Transactions!F:F,KPI!K9)) -> 27438101 | M9: =SUMIFS( Budget!E:E, Budget!C:C, KPI!K9, Budget!A:A, KPI!J9 ) -> 19043590 | N9: =L9-M9 -> 8394510.8
A10: 2023 | B10: Online | C10: =SUMIFS(Financial_Transactions!C:C,Financial_Transactions!D:D,"Revenue",Financial_Transactions!M:M,KPI!A10,Financial_Transactions!F:F,KPI!B10) -> 1.6668913e+08 | D10: =ABS(SUMIFS(Financial_Transactions!C:C,Financial_Transactions!D:D,"Expense",Financial_Transactions!M:M,KPI!A10,Financial_Transactions!F:F,KPI!B10)) -> 27438101 | J10: 2022 | K10: Enterprise | L10: =ABS(SUMIFS(Financial_Transactions!C:C,Financial_Transactions!D:D,"Expense",Financial_Transactions!F:F,KPI!K10,Financial_Transactions!M:M,KPI!J10)) -> 28023931 | M10: =SUMIFS( Budget!E:E, Budget!C:C, KPI!K10, Budget!A:A, KPI!J10 ) -> 15977111 | N10: =L10-M10 -> 12046820
A11: 2022 | B11: Enterprise | C11: =SUMIFS(Financial_Transactions!C:C,Financial_Transactions!D:D,"Revenue",Financial_Transactions!M:M,KPI!A11,Financial_Transactions!F:F,KPI!B11) -> 1.1706183e+08 | D11: =ABS(SUMIFS(Financial_Transactions!C:C,Financial_Transactions!D:D,"Expense",Financial_Transactions!M:M,KPI!A11,Financial_Transactions!F:F,KPI!B11)) -> 28023931 | J11: 2022 | K11: Retail | L11: =ABS(SUMIFS(Financial_Transactions!C:C,Financial_Transactions!D:D,"Expense",Financial_Transactions!F:F,KPI!K11,Financial_Transactions!M:M,KPI!J11)) -> 27971942 | M11: =SUMIFS( Budget!E:E, Budget!C:C, KPI!K11, Budget!A:A, KPI!J11 ) -> 17749649 | N11: =L11-M11 -> 10222293
A12: 2022 | B12: Retail | C12: =SUMIFS(Financial_Transactions!C:C,Financial_Transactions!D:D,"Revenue",Financial_Transactions!M:M,KPI!A12,Financial_Transactions!F:F,KPI!B12) -> 1.2952051e+08 | D12: =ABS(SUMIFS(Financial_Transactions!C:C,Financial_Transactions!D:D,"Expense",Financial_Transactions!M:M,KPI!A12,Financial_Transactions!F:F,KPI!B12)) -> 27971942 | J12: 2022 | K12: Online | L12: =ABS(SUMIFS(Financial_Transactions!C:C,Financial_Transactions!D:D,"Expense",Financial_Transactions!F:F,KPI!K12,Financial_Transactions!M:M,KPI!J12)) -> 27865437 | M12: =SUMIFS( Budget!E:E, Budget!C:C, KPI!K12, Budget!A:A, KPI!J12 ) -> 18090420 | N12: =L12-M12 -> 9775016.9
A13: 2022 | B13: Online | C13: =SUMIFS(Financial_Transactions!C:C,Financial_Transactions!D:D,"Revenue",Financial_Transactions!M:M,KPI!A13,Financial_Transactions!F:F,KPI!B13) -> 1.3084379e+08 | D13: =ABS(SUMIFS(Financial_Transactions!C:C,Financial_Transactions!D:D,"Expense",Financial_Transactions!M:M,KPI!A13,Financial_Transactions!F:F,KPI!B13)) -> 27865437
A15: Expense per vendor | E15: COST PER EMPLOYEE BY BUSINESS UNIT | J15: REVENUE PER CUSTOMER KPI
A17: Business Unit | B17: Expense per Vendor | E17: Business Unit | F17: Cost per employee | J17: Business Unit | K17: Revenue per Customer
A18: Enterprise | B18: {=ABS(SUMIFS( Financial_Transactions!C:C, Financial_Transactions!D:D,"Expense", Financial_Transactions!F:F,KPI!A18 )/COUNTA(_xlfn.UNIQUE(_xlfn._xlws.FILTER(Financial_Transactions!I:I,(Financial_Transactions!F:F=KPI!A18)*(Financial_Transactions!D:D="Expense")))))} -> 475188.49 | E18: Enterprise | F18: =SUMIFS(Headcount!G:G,Headcount!C:C,KPI!E18)/COUNTA(Headcount!A:A) -> 337313.96 | J18: Enterprise | K18: {=SUMIFS(Financial_Transactions!C:C,Financial_Transactions!D:D,"Revenue",Financial_Transactions!F:F,KPI!J18,Financial_Transactions!K:K,"valid")/COUNTA(_xlfn.UNIQUE(_xlfn._xlws.FILTER(Financial_Transactions!H:H,(Financial_Transactions!D:D="Revenue")*(Financial_Transactions!F:F=KPI!J18)*(Financial_Transactions!K:K="Valid"))))} -> 760532.99
A19: Retail | B19: {=ABS(SUMIFS( Financial_Transactions!C:C, Financial_Transactions!D:D,"Expense", Financial_Transactions!F:F,KPI!A19 )/COUNTA(_xlfn.UNIQUE(_xlfn._xlws.FILTER(Financial_Transactions!I:I,(Financial_Transactions!F:F=KPI!A19)*(Financial_Transactions!D:D="Expense")))))} -> 461792.86 | E19: Retail | F19: =SUMIFS(Headcount!G:G,Headcount!C:C,KPI!E19)/COUNTA(Headcount!A:A) -> 364607.16 | J19: Retail | K19: {=SUMIFS(Financial_Transactions!C:C,Financial_Transactions!D:D,"Revenue",Financial_Transactions!F:F,KPI!J19,Financial_Transactions!K:K,"valid")/COUNTA(_xlfn.UNIQUE(_xlfn._xlws.FILTER(Financial_Transactions!H:H,(Financial_Transactions!D:D="Revenue")*(Financial_Transactions!F:F=KPI!J19)*(Financial_Transactions!K:K="Valid"))))} -> 772103.96
A20: Online | B20: {=ABS(SUMIFS( Financial_Transactions!C:C, Financial_Transactions!D:D,"Expense", Financial_Transactions!F:F,KPI!A20 )/COUNTA(_xlfn.UNIQUE(_xlfn._xlws.FILTER(Financial_Transactions!I:I,(Financial_Transactions!F:F=KPI!A20)*(Financial_Transactions!D:D="Expense")))))} -> 460862.81 | E20: Online | F20: =SUMIFS(Headcount!G:G,Headcount!C:C,KPI!E20)/COUNTA(Headcount!A:A) -> 406663.82 | J20: Online | K20: {=SUMIFS(Financial_Transactions!C:C,Financial_Transactions!D:D,"Revenue",Financial_Transactions!F:F,KPI!J20,Financial_Transactions!K:K,"valid")/COUNTA(_xlfn.UNIQUE(_xlfn._xlws.FILTER(Financial_Transactions!H:H,(Financial_Transactions!D:D="Revenue")*(Financial_Transactions!F:F=KPI!J20)*(Financial_Transactions!K:K="Valid"))))} -> 799819.68

Sheet DISTRIBUTION ANALYSIS (HISTOGRA
E1: DISTRIBUTION ANALYSIS (HISTOGRAMS)
A4: Objective | B4: Understand how Revenue, Expense, Profit, and Budget Variance values are spread and whether they are skewed, concentrated, or volatile.
A22: Interpretation | J22: Interpretation
A23: Distribution is right-skewed | J23: Distribution is relatively stable
A24: Majority of transactions are low-to-mid value | J24: Most expenses fall within a narrow range
A25: Few high-value revenue transactions dominate totals | J25: Suggests controlled cost structure
A26: Indicates revenue concentration risk | J26: Limited extreme expense events
A45: Interpretation | J45: Interpretation
A46: Distribution spans both positive and negative values | J46: Distribution skewed toward positive values
A47: High spread indicates profit volatility | J47: Indicates frequent budget overruns
A48: Presence of loss-making transactions | J48: Variance magnitude differs across business units
A49: Profitability not uniform across periods | J49: Distribution based on aggregated budget records, resulting in fewer observations.

Sheet EDA_Outlier_Analysis
E2: OUTLIER ANALYSIS — IQR METHOD
A5: Revenue Outlier Analysis | E5: Expense Outlier Analysis | H5: PROFIT OUTLIER ANALYSIS | L5: BUDGET VARIANCE OUTLIER ANALYSIS
A6: Statistic | C6: Value | E6: Statistic | F6: Value | H6: Statistic | I6: Value | L6: Statistic | M6: Value
A7: Q1 | C7: =_xlfn.QUARTILE.INC(Financial_Transactions!O:O,1) -> 121379.81 | E7: Q1 | F7: =_xlfn.QUARTILE.INC(Financial_Transactions!P:P,1) -> 27137.34 | H7: Q1 | I7: =_xlfn.QUARTILE.INC(Financial_Transactions!N:N,1) -> -33812.21 | L7: Q1 | M7: =_xlfn.QUARTILE.INC(Budget!H:H,1) -> 6460452.4
A8: Q3 | C8: =_xlfn.QUARTILE.INC(Financial_Transactions!O:O,3) -> 190384.74 | E8: Q3 | F8: =_xlfn.QUARTILE.INC(Financial_Transactions!P:P,3) -> 53648.5 | H8: Q3 | I8: =_xlfn.QUARTILE.INC(Financial_Transactions!N:N,3) -> 157303.55 | L8: Q3 | M8: =_xlfn.QUARTILE.INC(Budget!H:H,3) -> 10191659
A9: IQR | C9: =C8-C7 -> 69004.928 | E9: IQR | F9: =F8-F7 -> 26511.16 | H9: IQR | I9: =I8-I7 -> 191115.76 | L9: IQR | M9: =M8-M7 -> 3731206.1
A10: Lower Bound | C10: =C7-1.5*C9 -> 17872.419 | E10: Lower Bound | F10: =F7-1.5*F9 -> -12629.4 | H10: Lower Bound | I10: =I7-1.5*I9 -> -320485.85 | L10: Lower Bound | M10: =M7-1.5*M9 -> 863643.21
A11: Upper Bound | C11: =C8+1.5*C9 -> 293892.13 | E11: Upper Bound | F11: =F8+1.5*F9 -> 93415.24 | H11: Upper Bound | I11: =I8+1.5*I9 -> 443977.2 | L11: Upper Bound | M11: =M8+1.5*M9 -> 15788468
A12: Total Observations | C12: =COUNT(Financial_Transactions!O:O) -> 5514 | E12: Total Observations | F12: =COUNT(Financial_Transactions!P:P) -> 4125 | H12: Total Observations | I12: =COUNT(Financial_Transactions!N:N) -> 10400 | L12: Total Observations | M12: =COUNT(Budget!H:H) -> 72
A13: Outlier Count | C13: =COUNTIF(Financial_Transactions!Q:Q,"Outlier") -> 51 | E13: Outlier Count | F13: =COUNTIF(Financial_Transactions!R:R,"Outlier") -> 2062 | H13: Outlier Count | I13: =COUNTIF(Financial_Transactions!S:S,"Outlier") -> 0 | L13: Outlier Count | M13: =COUNTIF(Budget!I:I,"Outlier") -> 0
A14: % Outliers | C14: =C13/C12 -> 0.0092491839 | E14: % Outliers | F14: =F13/F12 -> 0.49987879 | H14: % Outliers | I14: =I13/I11 -> 0 | L14: % Outliers | M14: =M13/M12 -> 0

Sheet EDA_Time_Series
D1: EXPLORATORY DATA ANALYSIS (EDA) — TIME SERIES & TREND ANALYSIS
A4: Objective: Analyze monthly trends in Revenue, Expense, Profit, and Budget Variance to identify growth patterns, seasonality, and volatility across 2022–2023.
A6: Year | B6: Month_no | C6: Month_name | D6: Revenue | E6: Expense | F6: Profit | G6: Budget Variance | H6: Expense_helper_col
A7: 2022 | B7: 1 | C7: =TEXT(DATE(A7, B7, 1), "mmmm") -> January | D7: =SUMIFS(Financial_Transactions!C:C,Financial_Transactions!D:D,"Revenue",Financial_Transactions!M:M,EDA_Time_Series!A7,Financial_Transactions!L:L,EDA_Time_Series!B7) -> 25538098 | E7: =SUMIFS(Financial_Transactions!C:C,Financial_Transactions!D:D,"Expense",Financial_Transactions!M:M,EDA_Time_Series!A7,Financial_Transactions!L:L,EDA_Time_Series!B7) -> -7399263.9 | F7: =D7-E7 -> 32937362 | G7: =SUMIFS(Budget!H:H,Budget!A:A,EDA_Time_Series!A7,Budget!B:B,EDA_Time_Series!B7) -> 14748460 | H7: =ABS(E7) -> 7399263.9
A8: 2022 | B8: 2 | C8: =TEXT(DATE(A8, B8, 1), "mmmm") -> February | D8: =SUMIFS(Financial_Transactions!C:C,Financial_Transactions!D:D,"Revenue",Financial_Transactions!M:M,EDA_Time_Series!A8,Financial_Transactions!L:L,EDA_Time_Series!B8) -> 22787660 | E8: =SUMIFS(Financial_Transactions!C:C,Financial_Transactions!D:D,"Expense",Financial_Transactions!M:M,EDA_Time_Series!A8,Financial_Transactions!L:L,EDA_Time_Series!B8) -> -6128841.5 | F8: =D8-E8 -> 28916501 | G8: =SUMIFS(Budget!H:H,Budget!A:A,EDA_Time_Series!A8,Budget!B:B,EDA_Time_Series!B8) -> 13528123 | H8: =ABS(E8) -> 6128841.5
A9: 2022 | B9: 3 | C9: =TEXT(DATE(A9, B9, 1), "mmmm") -> March | D9: =SUMIFS(Financial_Transactions!C:C,Financial_Transactions!D:D,"Revenue",Financial_Transactions!M:M,EDA_Time_Series!A9,Financial_Transactions!L:L,EDA_Time_Series!B9) -> 25839879 | E9: =SUMIFS(Financial_Transactions!C:C,Financial_Transactions!D:D,"Expense",Financial_Transactions!M:M,EDA_Time_Series!A9,Financial_Transactions!L:L,EDA_Time_Series!B9) -> -6837846.5 | F9: =D9-E9 -> 32677725 | G9: =SUMIFS(Budget!H:H,Budget!A:A,EDA_Time_Series!A9,Budget!B:B,EDA_Time_Series!B9) -> 15990706 | H9: =ABS(E9) -> 6837846.5
A10: 2022 | B10: 4 | C10: =TEXT(DATE(A10, B10, 1), "mmmm") -> April | D10: =SUMIFS(Financial_Transactions!C:C,Financial_Transactions!D:D,"Revenue",Financial_Transactions!M:M,EDA_Time_Series!A10,Financial_Transactions!L:L,EDA_Time_Series!B10) -> 32862479 | E10: =SUMIFS(Financial_Transactions!C:C,Financial_Transactions!D:D,"Expense",Financial_Transactions!M:M,EDA_Time_Series!A10,Financial_Transactions!L:L,EDA_Time_Series!B10) -> -7543282 | F10: =D10-E10 -> 40405761 | G10: =SUMIFS(Budget!H:H,Budget!A:A,EDA_Time_Series!A10,Budget!B:B,EDA_Time_Series!B10) -> 21766286 | H10: =ABS(E10) -> 7543282
